2020-06-27 14:50:45,425 INFO: Microblog startup [in /home/mohamed/Documents/web/flask/microblog/app/__init__.py:50]
2020-06-27 14:51:07,856 INFO: Microblog startup [in /home/mohamed/Documents/web/flask/microblog/app/__init__.py:50]
2020-06-30 14:22:00,607 INFO: Microblog startup [in /home/mohamed/Documents/web/flask/microblog/app/__init__.py:50]
2020-06-30 14:40:49,256 INFO: Microblog startup [in /home/mohamed/Documents/web/flask/microblog/app/__init__.py:50]
2020-06-30 14:43:04,515 INFO: Microblog startup [in /home/mohamed/Documents/web/flask/microblog/app/__init__.py:50]
2020-07-04 14:39:36,982 INFO: Microblog startup [in /home/mohamed/Documents/web/flask/microblog/app/__init__.py:50]
2020-07-04 14:41:29,860 ERROR: Exception on / [GET] [in /usr/local/lib/python3.7/dist-packages/flask/app.py:1891]
Traceback (most recent call last):
  File "/usr/local/lib/python3.7/dist-packages/flask/app.py", line 2446, in wsgi_app
    response = self.full_dispatch_request()
  File "/usr/local/lib/python3.7/dist-packages/flask/app.py", line 1951, in full_dispatch_request
    rv = self.handle_user_exception(e)
  File "/usr/local/lib/python3.7/dist-packages/flask/app.py", line 1820, in handle_user_exception
    reraise(exc_type, exc_value, tb)
  File "/usr/local/lib/python3.7/dist-packages/flask/_compat.py", line 39, in reraise
    raise value
  File "/usr/local/lib/python3.7/dist-packages/flask/app.py", line 1949, in full_dispatch_request
    rv = self.dispatch_request()
  File "/usr/local/lib/python3.7/dist-packages/flask/app.py", line 1935, in dispatch_request
    return self.view_functions[rule.endpoint](**req.view_args)
  File "/usr/local/lib/python3.7/dist-packages/flask_login/utils.py", line 272, in decorated_view
    return func(*args, **kwargs)
  File "/home/mohamed/Documents/web/flask/microblog/app/routes.py", line 32, in home
    posts = current_user.followed_posts.all()
AttributeError: 'function' object has no attribute 'all'
2020-07-04 14:42:03,681 INFO: Microblog startup [in /home/mohamed/Documents/web/flask/microblog/app/__init__.py:50]
2020-07-04 14:43:47,374 INFO: Microblog startup [in /home/mohamed/Documents/web/flask/microblog/app/__init__.py:50]
2020-07-04 14:44:00,298 ERROR: Exception on /explore [GET] [in /usr/local/lib/python3.7/dist-packages/flask/app.py:1891]
Traceback (most recent call last):
  File "/usr/local/lib/python3.7/dist-packages/flask/app.py", line 2446, in wsgi_app
    response = self.full_dispatch_request()
  File "/usr/local/lib/python3.7/dist-packages/flask/app.py", line 1951, in full_dispatch_request
    rv = self.handle_user_exception(e)
  File "/usr/local/lib/python3.7/dist-packages/flask/app.py", line 1820, in handle_user_exception
    reraise(exc_type, exc_value, tb)
  File "/usr/local/lib/python3.7/dist-packages/flask/_compat.py", line 39, in reraise
    raise value
  File "/usr/local/lib/python3.7/dist-packages/flask/app.py", line 1949, in full_dispatch_request
    rv = self.dispatch_request()
  File "/usr/local/lib/python3.7/dist-packages/flask/app.py", line 1935, in dispatch_request
    return self.view_functions[rule.endpoint](**req.view_args)
  File "/usr/local/lib/python3.7/dist-packages/flask_login/utils.py", line 272, in decorated_view
    return func(*args, **kwargs)
  File "/home/mohamed/Documents/web/flask/microblog/app/routes.py", line 145, in explore
    posts = Post.query.order_by(Post.timestamp.desc).all()
  File "<string>", line 2, in order_by
  File "/usr/local/lib/python3.7/dist-packages/sqlalchemy/orm/base.py", line 220, in generate
    fn(self, *args[1:], **kw)
  File "/usr/local/lib/python3.7/dist-packages/sqlalchemy/orm/query.py", line 1850, in order_by
    criterion = self._adapt_col_list(criterion)
  File "/usr/local/lib/python3.7/dist-packages/sqlalchemy/orm/query.py", line 312, in _adapt_col_list
    for o in cols
  File "/usr/local/lib/python3.7/dist-packages/sqlalchemy/orm/query.py", line 312, in <listcomp>
    for o in cols
  File "/usr/local/lib/python3.7/dist-packages/sqlalchemy/sql/elements.py", line 4536, in _literal_as_label_reference
    return _literal_as_text(element)
  File "/usr/local/lib/python3.7/dist-packages/sqlalchemy/sql/elements.py", line 4579, in _literal_as_text
    return _literal_as(element, _no_text_coercion)
  File "/usr/local/lib/python3.7/dist-packages/sqlalchemy/sql/elements.py", line 4571, in _literal_as
    "instead" % type(element)
sqlalchemy.exc.ArgumentError: SQL expression object expected, got object of type <class 'method'> instead
2020-07-04 14:44:59,012 INFO: Microblog startup [in /home/mohamed/Documents/web/flask/microblog/app/__init__.py:50]
2020-07-04 14:48:03,936 INFO: Microblog startup [in /home/mohamed/Documents/web/flask/microblog/app/__init__.py:50]
2020-07-04 14:50:04,532 ERROR: Exception on /home/user/pysec [GET] [in /usr/local/lib/python3.7/dist-packages/flask/app.py:1891]
Traceback (most recent call last):
  File "/usr/local/lib/python3.7/dist-packages/flask/app.py", line 2446, in wsgi_app
    response = self.full_dispatch_request()
  File "/usr/local/lib/python3.7/dist-packages/flask/app.py", line 1951, in full_dispatch_request
    rv = self.handle_user_exception(e)
  File "/usr/local/lib/python3.7/dist-packages/flask/app.py", line 1820, in handle_user_exception
    reraise(exc_type, exc_value, tb)
  File "/usr/local/lib/python3.7/dist-packages/flask/_compat.py", line 39, in reraise
    raise value
  File "/usr/local/lib/python3.7/dist-packages/flask/app.py", line 1949, in full_dispatch_request
    rv = self.dispatch_request()
  File "/usr/local/lib/python3.7/dist-packages/flask/app.py", line 1935, in dispatch_request
    return self.view_functions[rule.endpoint](**req.view_args)
  File "/usr/local/lib/python3.7/dist-packages/flask_login/utils.py", line 272, in decorated_view
    return func(*args, **kwargs)
  File "/home/mohamed/Documents/web/flask/microblog/app/routes.py", line 83, in user
    return render_template('user.html', title=username, posts=posts, user=user)
  File "/usr/local/lib/python3.7/dist-packages/flask/templating.py", line 140, in render_template
    ctx.app,
  File "/usr/local/lib/python3.7/dist-packages/flask/templating.py", line 120, in _render
    rv = template.render(context)
  File "/usr/local/lib/python3.7/dist-packages/jinja2/environment.py", line 1090, in render
    self.environment.handle_exception()
  File "/usr/local/lib/python3.7/dist-packages/jinja2/environment.py", line 832, in handle_exception
    reraise(*rewrite_traceback_stack(source=source))
  File "/usr/local/lib/python3.7/dist-packages/jinja2/_compat.py", line 28, in reraise
    raise value.with_traceback(tb)
  File "/home/mohamed/Documents/web/flask/microblog/app/templates/user.html", line 1, in top-level template code
    {% extends "base.html" %}
  File "/home/mohamed/Documents/web/flask/microblog/app/templates/base.html", line 27, in top-level template code
    {% block contents %}
  File "/home/mohamed/Documents/web/flask/microblog/app/templates/user.html", line 16, in block "contents"
    {{ form.hidden_tag() }}
  File "/usr/local/lib/python3.7/dist-packages/jinja2/environment.py", line 471, in getattr
    return getattr(obj, attribute)
jinja2.exceptions.UndefinedError: 'form' is undefined
2020-07-04 14:55:05,852 INFO: Microblog startup [in /home/mohamed/Documents/web/flask/microblog/app/__init__.py:50]
2020-07-04 14:56:41,560 INFO: Microblog startup [in /home/mohamed/Documents/web/flask/microblog/app/__init__.py:50]
2020-07-04 14:57:06,512 INFO: Microblog startup [in /home/mohamed/Documents/web/flask/microblog/app/__init__.py:50]
2020-07-04 14:58:11,306 ERROR: Exception on /explore [GET] [in /usr/local/lib/python3.7/dist-packages/flask/app.py:1891]
Traceback (most recent call last):
  File "/usr/local/lib/python3.7/dist-packages/flask/app.py", line 2446, in wsgi_app
    response = self.full_dispatch_request()
  File "/usr/local/lib/python3.7/dist-packages/flask/app.py", line 1951, in full_dispatch_request
    rv = self.handle_user_exception(e)
  File "/usr/local/lib/python3.7/dist-packages/flask/app.py", line 1820, in handle_user_exception
    reraise(exc_type, exc_value, tb)
  File "/usr/local/lib/python3.7/dist-packages/flask/_compat.py", line 39, in reraise
    raise value
  File "/usr/local/lib/python3.7/dist-packages/flask/app.py", line 1949, in full_dispatch_request
    rv = self.dispatch_request()
  File "/usr/local/lib/python3.7/dist-packages/flask/app.py", line 1935, in dispatch_request
    return self.view_functions[rule.endpoint](**req.view_args)
  File "/usr/local/lib/python3.7/dist-packages/flask_login/utils.py", line 272, in decorated_view
    return func(*args, **kwargs)
  File "/home/mohamed/Documents/web/flask/microblog/app/routes.py", line 146, in explore
    return render_template('index.html', title='Explore', posts=posts)
  File "/usr/local/lib/python3.7/dist-packages/flask/templating.py", line 140, in render_template
    ctx.app,
  File "/usr/local/lib/python3.7/dist-packages/flask/templating.py", line 120, in _render
    rv = template.render(context)
  File "/usr/local/lib/python3.7/dist-packages/jinja2/environment.py", line 1090, in render
    self.environment.handle_exception()
  File "/usr/local/lib/python3.7/dist-packages/jinja2/environment.py", line 832, in handle_exception
    reraise(*rewrite_traceback_stack(source=source))
  File "/usr/local/lib/python3.7/dist-packages/jinja2/_compat.py", line 28, in reraise
    raise value.with_traceback(tb)
  File "/home/mohamed/Documents/web/flask/microblog/app/templates/index.html", line 1, in top-level template code
    {% extends "base.html" %}
  File "/home/mohamed/Documents/web/flask/microblog/app/templates/base.html", line 27, in top-level template code
    {% block contents %}
  File "/home/mohamed/Documents/web/flask/microblog/app/templates/index.html", line 33, in block "contents"
    {% include '_post.html' %}
  File "/home/mohamed/Documents/web/flask/microblog/app/templates/_post.html", line 4, in top-level template code
    <img src="{{ post.author.avatar(36) }}">
jinja2.exceptions.UndefinedError: 'None' has no attribute 'avatar'
2020-07-04 15:37:50,619 INFO: Microblog startup [in /home/mohamed/Documents/web/flask/microblog/app/__init__.py:52]
